Workbook
Name cacheRange: Summary!$J$7,Summary!$K$7,Summary!$J$11,Summary!$K$11,Summary!$J$15,Summary!$K$15,Summary!$J$19,Summary!$K$19,Summary!$J$23,Summary!$K$23,Summary!$J$27,Summary!$K$27,Summary!$J$31,Summary!$K$31
Name performanceRange: Summary!$L$6:$L$35
Name performanceValueRange: Summary!$L$6,Summary!$L$7,Summary!$L$10,Summary!$L$11,Summary!$L$14,Summary!$L$15,Summary!$L$18,Summary!$L$19,Summary!$L$22,Summary!$L$23,Summary!$L$26,Summary!$L$27,Summary!$L$30,Summary!$L$31

Sheet Summary
D2: PageSpeed Insights
B3: Production | D3: Performance
B4: Page | C4: Device | D4: With Cache | E4: Without Cache
J5: Best | K5: Worst | L5: Performance Value | M5: Device Selector | N5: Cell with Highest | O5: Cell with Lowest
G6: ="The best recorded performance score was in "&J6&" devices "& J7 &", at "& L6 &CHAR(10)& "The worst recorded performance score was in "& K6 &" devices "& K7 &", at "&L7 &CHAR(10)& "Refer to "&B7&" tab for the best and worst insight, links for full diagnostic readings and recommendations for improvement." -> The best recorded performance score was in Desktop devices with and without cache, at 0 The worst recorded performance score was in Desktop devices with and without cache, at 0 Refer to 01_Home tab for the best and worst insight, links for full diagnostic readings and recommendations for improvement. | I6: Device: | J6: {=INDIRECT(M6)} -> Desktop | K6: {=INDIRECT(M7)} -> Desktop | L6: =MAX(D7:E8) -> 0 | M6: =IF(LEFT(N6,1)="D", CHAR(CODE(LEFT(N6,1)) - 1) & MID(N6,2,99), CHAR(CODE(LEFT(N6,1)) - 2) & MID(N6,2,99) ) -> C7 | N6: {=ADDRESS(MIN(IF(D7:E8=L6,ROW(D7:E8))), MIN(IF(D7:E8=L6,COLUMN(D7:E8))), 4)} -> D7 | O6: {=ADDRESS(MIN(IF(D7:E8=L7,ROW(D7:E8))), MIN(IF(D7:E8=L7,COLUMN(D7:E8))), 4)} -> D7
B7: 01_Home | C7: Desktop | I7: Cache: | J7: =IF(J6="Desktop",IF(D7=E7,"with and without cache",(IF(D7>E7,"with cache","without cache"))),IF(D8=E8,"with and without cache",(IF(D8>E8,"with cache","without cache")))) -> with and without cache | K7: =IF(K6="Desktop",IF(D7=E7,"with and without cache",IF(D7<E7,"with cache","without cache")),IF(D8=E8,"with and without cache",IF(D8<E8,"with cache","without cache"))) -> with and without cache | L7: =MIN(D7:E8) -> 0 | M7: =IF(LEFT(O6,1)="D", CHAR(CODE(LEFT(O6,1)) - 1) & MID(O6,2,99), CHAR(CODE(LEFT(O6,1)) - 2) & MID(O6,2,99) ) -> C7
C8: Mobile
L9: Performance Value
G10: ="The best recorded performance score was in "&J10&" devices "& J11 &", at "& L10 &CHAR(10)& "The worst recorded performance score was in "& K10 &" devices "& K11 &", at "&L11 &CHAR(10)& "Refer to "&B11&" tab for the best and worst insight, links for full diagnostic readings and recommendations for improvement." -> The best recorded performance score was in Desktop devices with and without cache, at 0 The worst recorded performance score was in Desktop devices with and without cache, at 0 Refer to 02_Testing tab for the best and worst insight, links for full diagnostic readings and recommendations for improvement. | I10: Device: | J10: {=INDIRECT(M10)} -> Desktop | K10: {=INDIRECT(M11)} -> Desktop | L10: =MAX(D11:E12) -> 0 | M10: =IF(LEFT(N10,1)="D", CHAR(CODE(LEFT(N10,1)) - 1) & MID(N10,2,99), CHAR(CODE(LEFT(N10,1)) - 2) & MID(N10,2,99) ) -> C11 | N10: {=ADDRESS(MIN(IF(D11:E12=L10,ROW(D11:E12))), MIN(IF(D11:E12=L10,COLUMN(D11:E12))), 4)} -> D11 | O10: {=ADDRESS(MIN(IF(D11:E12=L11,ROW(D11:E12))), MIN(IF(D11:E12=L11,COLUMN(D11:E12))), 4)} -> D11
B11: 02_Testing | C11: Desktop | I11: Cache: | J11: =IF(J10="Desktop",IF(D11=E11,"with and without cache",(IF(D11>E11,"with cache","without cache"))),IF(D12=E12,"with and without cache",(IF(D12>E12,"with cache","without cache")))) -> with and without cache | K11: =IF(K10="Desktop",IF(D11=E11,"with and without cache",IF(D11<E11,"with cache","without cache")),IF(D12=E12,"with and without cache",IF(D12<E12,"with cache","without cache"))) -> with and without cache | L11: =MIN(D11:E12) -> 0 | M11: =IF(LEFT(O10,1)="D", CHAR(CODE(LEFT(O10,1)) - 1) & MID(O10,2,99), CHAR(CODE(LEFT(O10,1)) - 2) & MID(O10,2,99) ) -> C11
C12: Mobile
L13: Performance Value
G14: ="The best recorded performance score was in "&J14&" devices "& J15 &", at "& L14 &CHAR(10)& "The worst recorded performance score was in "& K14 &" devices "& K15 &", at "&L15 &CHAR(10)& "Refer to "&B15&" tab for the best and worst insight, links for full diagnostic readings and recommendations for improvement." -> The best recorded performance score was in Desktop devices with and without cache, at 0 The worst recorded performance score was in Desktop devices with and without cache, at 0 Refer to 03_About tab for the best and worst insight, links for full diagnostic readings and recommendations for improvement. | I14: Device: | J14: {=INDIRECT(M14)} -> Desktop | K14: {=INDIRECT(M15)} -> Desktop | L14: =MAX(D15:E16) -> 0 | M14: =IF(LEFT(N14,1)="D", CHAR(CODE(LEFT(N14,1)) - 1) & MID(N14,2,99), CHAR(CODE(LEFT(N14,1)) - 2) & MID(N14,2,99) ) -> C15 | N14: {=ADDRESS(MIN(IF(D15:E16=L14,ROW(D15:E16))), MIN(IF(D15:E16=L14,COLUMN(D15:E16))), 4)} -> D15 | O14: {=ADDRESS(MIN(IF(D15:E16=L15,ROW(D15:E16))), MIN(IF(D15:E16=L15,COLUMN(D15:E16))), 4)} -> D15
B15: 03_About | C15: Desktop | I15: Cache: | J15: =IF(J14="Desktop",IF(D15=E15,"with and without cache",(IF(D15>E15,"with cache","without cache"))),IF(D16=E16,"with and without cache",(IF(D16>E16,"with cache","without cache")))) -> with and without cache | K15: =IF(K14="Desktop",IF(D15=E15,"with and without cache",IF(D15<E15,"with cache","without cache")),IF(D16=E16,"with and without cache",IF(D16<E16,"with cache","without cache"))) -> with and without cache | L15: =MIN(D15:E16) -> 0 | M15: =IF(LEFT(O14,1)="D", CHAR(CODE(LEFT(O14,1)) - 1) & MID(O14,2,99), CHAR(CODE(LEFT(O14,1)) - 2) & MID(O14,2,99) ) -> C15
C16: Mobile
L17: Performance Value
G18: ="The best recorded performance score was in "&J18&" devices "& J19 &", at "& L18 &CHAR(10)& "The worst recorded performance score was in "& K18 &" devices "& K19 &", at "&L19 &CHAR(10)& "Refer to "&B19&" tab for the best and worst insight, links for full diagnostic readings and recommendations for improvement." -> The best recorded performance score was in Desktop devices with and without cache, at 0 The worst recorded performance score was in Desktop devices with and without cache, at 0 Refer to 04_News tab for the best and worst insight, links for full diagnostic readings and recommendations for improvement. | I18: Device: | J18: {=INDIRECT(M18)} -> Desktop | K18: {=INDIRECT(M19)} -> Desktop | L18: =MAX(D19:E20) -> 0 | M18: =IF(LEFT(N18,1)="D", CHAR(CODE(LEFT(N18,1)) - 1) & MID(N18,2,99), CHAR(CODE(LEFT(N18,1)) - 2) & MID(N18,2,99) ) -> C19 | N18: {=ADDRESS(MIN(IF(D19:E20=L18,ROW(D19:E20))), MIN(IF(D19:E20=L18,COLUMN(D19:E20))), 4)} -> D19 | O18: {=ADDRESS(MIN(IF(D19:E20=L19,ROW(D19:E20))), MIN(IF(D19:E20=L19,COLUMN(D19:E20))), 4)} -> D19
B19: 04_News | C19: Desktop | I19: Cache: | J19: =IF(J18="Desktop",IF(D19=E19,"with and without cache",(IF(D19>E19,"with cache","without cache"))),IF(D20=E20,"with and without cache",(IF(D20>E20,"with cache","without cache")))) -> with and without cache | K19: =IF(K18="Desktop",IF(D19=E19,"with and without cache",IF(D19<E19,"with cache","without cache")),IF(D20=E20,"with and without cache",IF(D20<E20,"with cache","without cache"))) -> with and without cache | L19: =MIN(D19:E20) -> 0 | M19: =IF(LEFT(O18,1)="D", CHAR(CODE(LEFT(O18,1)) - 1) & MID(O18,2,99), CHAR(CODE(LEFT(O18,1)) - 2) & MID(O18,2,99) ) -> C19
C20: Mobile
L21: Performance Value
G22: ="The best recorded performance score was in "&J22&" devices "& J23 &", at "& L22 &CHAR(10)& "The worst recorded performance score was in "& K22 &" devices "& K23 &", at "&L23 &CHAR(10)& "Refer to "&B23&" tab for the best and worst insight, links for full diagnostic readings and recommendations for improvement." -> The best recorded performance score was in Desktop devices with and without cache, at 0 The worst recorded performance score was in Desktop devices with and without cache, at 0 Refer to 05_Careers tab for the best and worst insight, links for full diagnostic readings and recommendations for improvement. | I22: Device: | J22: {=INDIRECT(M22)} -> Desktop | K22: {=INDIRECT(M23)} -> Desktop | L22: =MAX(D23:E24) -> 0 | M22: =IF(LEFT(N22,1)="D", CHAR(CODE(LEFT(N22,1)) - 1) & MID(N22,2,99), CHAR(CODE(LEFT(N22,1)) - 2) & MID(N22,2,99) ) -> C23 | N22: {=ADDRESS(MIN(IF(D23:E24=L22,ROW(D23:E24))), MIN(IF(D23:E24=L22,COLUMN(D23:E24))), 4)} -> D23 | O22: {=ADDRESS(MIN(IF(D23:E24=L23,ROW(D23:E24))), MIN(IF(D23:E24=L23,COLUMN(D23:E24))), 4)} -> D23
B23: 05_Careers | C23: Desktop | I23: Cache: | J23: =IF(J22="Desktop",IF(D23=E23,"with and without cache",(IF(D23>E23,"with cache","without cache"))),IF(D24=E24,"with and without cache",(IF(D24>E24,"with cache","without cache")))) -> with and without cache | K23: =IF(K22="Desktop",IF(D23=E23,"with and without cache",IF(D23<E23,"with cache","without cache")),IF(D24=E24,"with and without cache",IF(D24<E24,"with cache","without cache"))) -> with and without cache | L23: =MIN(D23:E24) -> 0 | M23: =IF(LEFT(O22,1)="D", CHAR(CODE(LEFT(O22,1)) - 1) & MID(O22,2,99), CHAR(CODE(LEFT(O22,1)) - 2) & MID(O22,2,99) ) -> C23
C24: Mobile
L25: Performance Value
G26: ="The best recorded performance score was in "&J26&" devices "& J27 &", at "& L26 &CHAR(10)& "The worst recorded performance score was in "& K26 &" devices "& K27 &", at "&L27 &CHAR(10)& "Refer to "&B27&" tab for the best and worst insight, links for full diagnostic readings and recommendations for improvement." -> The best recorded performance score was in Desktop devices with and without cache, at 0 The worst recorded performance score was in Desktop devices with and without cache, at 0 Refer to 06_Contact tab for the best and worst insight, links for full diagnostic readings and recommendations for improvement. | I26: Device: | J26: {=INDIRECT(M26)} -> Desktop | K26: {=INDIRECT(M27)} -> Desktop | L26: =MAX(D27:E28) -> 0 | M26: =IF(LEFT(N26,1)="D", CHAR(CODE(LEFT(N26,1)) - 1) & MID(N26,2,99), CHAR(CODE(LEFT(N26,1)) - 2) & MID(N26,2,99) ) -> C27 | N26: {=ADDRESS(MIN(IF(D27:E28=L26,ROW(D27:E28))), MIN(IF(D27:E28=L26,COLUMN(D27:E28))), 4)} -> D27 | O26: {=ADDRESS(MIN(IF(D27:E28=L27,ROW(D27:E28))), MIN(IF(D27:E28=L27,COLUMN(D27:E28))), 4)} -> D27
B27: 06_Contact | C27: Desktop | I27: Cache: | J27: =IF(J26="Desktop",IF(D27=E27,"with and without cache",(IF(D27>E27,"with cache","without cache"))),IF(D28=E28,"with and without cache",(IF(D28>E28,"with cache","without cache")))) -> with and without cache | K27: =IF(K26="Desktop",IF(D27=E27,"with and without cache",IF(D27<E27,"with cache","without cache")),IF(D28=E28,"with and without cache",IF(D28<E28,"with cache","without cache"))) -> with and without cache | L27: =MIN(D27:E28) -> 0 | M27: =IF(LEFT(O26,1)="D", CHAR(CODE(LEFT(O26,1)) - 1) & MID(O26,2,99), CHAR(CODE(LEFT(O26,1)) - 2) & MID(O26,2,99) ) -> C27
C28: Mobile
L29: Performance Value
G30: ="The best recorded performance score was in "&J30&" devices "& J31 &", at "& L30 &CHAR(10)& "The worst recorded performance score was in "& K30 &" devices "& K31 &", at "&L31 &CHAR(10)& "Refer to "&B31&" tab for the best and worst insight, links for full diagnostic readings and recommendations for improvement." -> The best recorded performance score was in Desktop devices with and without cache, at 0 The worst recorded performance score was in Desktop devices with and without cache, at 0 Refer to 07_Privacy tab for the best and worst insight, links for full diagnostic readings and recommendations for improvement. | I30: Device: | J30: {=INDIRECT(M30)} -> Desktop | K30: {=INDIRECT(M31)} -> Desktop | L30: =MAX(D31:E32) -> 0 | M30: =IF(LEFT(N30,1)="D", CHAR(CODE(LEFT(N30,1)) - 1) & MID(N30,2,99), CHAR(CODE(LEFT(N30,1)) - 2) & MID(N30,2,99) ) -> C31 | N30: {=ADDRESS(MIN(IF(D31:E32=L30,ROW(D31:E32))), MIN(IF(D31:E32=L30,COLUMN(D31:E32))), 4)} -> D31 | O30: {=ADDRESS(MIN(IF(D31:E32=L31,ROW(D31:E32))), MIN(IF(D31:E32=L31,COLUMN(D31:E32))), 4)} -> D31
B31: 07_Privacy | C31: Desktop | I31: Cache: | J31: =IF(J30="Desktop",IF(D31=E31,"with and without cache",(IF(D31>E31,"with cache","without cache"))),IF(D32=E32,"with and without cache",(IF(D32>E32,"with cache","without cache")))) -> with and without cache | K31: =IF(K30="Desktop",IF(D31=E31,"with and without cache",IF(D31<E31,"with cache","without cache")),IF(D32=E32,"with and without cache",IF(D32<E32,"with cache","without cache"))) -> with and without cache | L31: =MIN(D31:E32) -> 0 | M31: =IF(LEFT(O30,1)="D", CHAR(CODE(LEFT(O30,1)) - 1) & MID(O30,2,99), CHAR(CODE(LEFT(O30,1)) - 2) & MID(O30,2,99) ) -> C31
C32: Mobile
L33: Performance Value
G34: ="The best recorded performance score was in "&J34&" devices "& J35 &", at "& L34 &CHAR(10)& "The worst recorded performance score was in "& K34 &" devices "& K35 &", at "&L35 &CHAR(10)& "Refer to "&B35&" tab for the best and worst insight, links for full diagnostic readings and recommendations for improvement." -> The best recorded performance score was in Desktop devices with and without cache, at 0 The worst recorded performance score was in Desktop devices with and without cache, at 0 Refer to 08_Game Testing tab for the best and worst insight, links for full diagnostic readings and recommendations for improvement. | I34: Device: | J34: {=INDIRECT(M34)} -> Desktop | K34: {=INDIRECT(M35)} -> Desktop | L34: =MAX(D35:E36) -> 0 | M34: =IF(LEFT(N34,1)="D", CHAR(CODE(LEFT(N34,1)) - 1) & MID(N34,2,99), CHAR(CODE(LEFT(N34,1)) - 2) & MID(N34,2,99) ) -> C35 | N34: {=ADDRESS(MIN(IF(D35:E36=L34,ROW(D35:E36))), MIN(IF(D35:E36=L34,COLUMN(D35:E36))), 4)} -> D35 | O34: {=ADDRESS(MIN(IF(D35:E36=L35,ROW(D35:E36))), MIN(IF(D35:E36=L35,COLUMN(D35:E36))), 4)} -> D35
B35: 08_Game Testing | C35: Desktop | I35: Cache: | J35: =IF(J34="Desktop",IF(D35=E35,"with and without cache",(IF(D35>E35,"with cache","without cache"))),IF(D36=E36,"with and without cache",(IF(D36>E36,"with cache","without cache")))) -> with and without cache | K35: =IF(K34="Desktop",IF(D35=E35,"with and without cache",IF(D35<E35,"with cache","without cache")),IF(D36=E36,"with and without cache",IF(D36<E36,"with cache","without cache"))) -> with and without cache | L35: =MIN(D35:E36) -> 0 | M35: =IF(LEFT(O34,1)="D", CHAR(CODE(LEFT(O34,1)) - 1) & MID(O34,2,99), CHAR(CODE(LEFT(O34,1)) - 2) & MID(O34,2,99) ) -> C35
C36: Mobile
C38: 0 to 49 | D38: Poor | G38: {=IFERROR( "The best recorded performance score was in the " & J46 & " page for " & INDIRECT(J43) & " devices " & J42 & ", at " & J39 & CHAR(10) & "Refer to " & J47 & " tab for the best insight, links for full diagnostic readings and recommendations for improvement." & CHAR(10) & CHAR(10) & "The worst recorded performance score was in the " & K46 & " page for " & INDIRECT(K43) & " devices " & K42 & ", at " & K39 & CHAR(10) & "Refer to " & K47 & " tab for the worst insight, links for full diagnostic readings and recommendations for improvement.", "Kindly, fill the Performance Score first!" )} -> Kindly, fill the Performance Score first! | I38: Name | J38: Best | K38: Worst
C39: 50 to 89 | D39: Needs Improvement | I39: Record performance value: | J39: =MAX(performanceRange) -> 0 | K39: =MIN(performanceRange) -> 0
C40: 90 to 100 | D40: Good | I40: Record performance value location: | J40: {=ADDRESS(MIN(IF(D7:E36=J39,ROW(D7:E36))), MIN(IF(D7:E36=J39,COLUMN(D7:E36))), 4)} -> D7 | K40: {=ADDRESS(MIN(IF(D7:E36=K39,ROW(D7:E36))), MIN(IF(D7:E36=K39,COLUMN(D7:E36))), 4)} -> D7
I41: With and Without Cache Value Location: | J41: =IF(LEFT(J40,1)="D", CHAR(CODE(LEFT(J40,1)) + 1)&MID(J40,2,99), J40) -> E7 | K41: =IF(LEFT(K40,1)="D", CHAR(CODE(LEFT(K40,1)) + 1)&MID(K40,2,99), K40) -> E7
I42: Cache Value: | J42: {=IF(LEFT(J40,1)="D", IF(J39=INDIRECT(J41), "with and without cache", "with cache"), IF(LEFT(J40,1)="E", "without cache", "Incorrect cache location" ) )} -> with and without cache | K42: {=IF(LEFT(K40,1)="D", IF(K39=INDIRECT(K41), "with and without cache", "with cache"), IF(LEFT(K40,1)="E", "without cache", "Incorrect cache location" ) )} -> with and without cache
...

Sheet 01_Home
C2: =Summary!D6 -> 0
B3: =Summary!B7 -> 01_Home | C3: Desktop | D3: With Cache
D4: Without Cache
C5: Mobile | D5: With Cache
D6: Without Cache
B8: Best Insight
B9: URL: | C9: =E3 -> 0
B10: Diagnostic: | C10: Defer offscreen images
B11: Recommendation: | C11: Learn how to defer offscreen images
B24: Worst Insight
B25: URL: | C25: =E5 -> 0
B26: Diagnostic:
B27: Recommendation:

Sheet 02_Testing
C2: =Summary!D10 -> 0
B3: =Summary!B11 -> 02_Testing | C3: Desktop | D3: With Cache
D4: Without Cache
C5: Mobile | D5: With Cache
D6: Without Cache
B8: Best Insight
B9: URL: | C9: =E3 -> 0
B10: Diagnostic: | C10: Defer offscreen images
B11: Recommendation: | C11: Learn how to defer offscreen images
B24: Worst Insight
B25: URL: | C25: =E5 -> 0
B26: Diagnostic:
B27: Recommendation:

Sheet 03_About
C2: =Summary!D14 -> 0
B3: =Summary!B15 -> 03_About | C3: Desktop | D3: With Cache
D4: Without Cache
C5: Mobile | D5: With Cache
D6: Without Cache
B8: Best Insight
B9: URL: | C9: =E3 -> 0
B10: Diagnostic: | C10: Defer offscreen images
B11: Recommendation: | C11: Learn how to defer offscreen images
B24: Worst Insight
B25: URL: | C25: =E5 -> 0
B26: Diagnostic:
B27: Recommendation:

Sheet 04_News
C2: =Summary!D18 -> 0
B3: =Summary!B19 -> 04_News | C3: Desktop | D3: With Cache
D4: Without Cache
C5: Mobile | D5: With Cache
D6: Without Cache
B8: Best Insight
B9: URL: | C9: =E3 -> 0
B10: Diagnostic: | C10: Defer offscreen images
B11: Recommendation: | C11: Learn how to defer offscreen images
B24: Worst Insight
B25: URL: | C25: =E5 -> 0
B26: Diagnostic:
B27: Recommendation:

Sheet 05_Careers
C2: =Summary!D22 -> 0
B3: =Summary!B23 -> 05_Careers | C3: Desktop | D3: With Cache
D4: Without Cache
C5: Mobile | D5: With Cache
D6: Without Cache
B8: Best Insight
B9: URL: | C9: =E3 -> 0
B10: Diagnostic: | C10: Defer offscreen images
B11: Recommendation: | C11: Learn how to defer offscreen images
B24: Worst Insight
B25: URL: | C25: =E5 -> 0
B26: Diagnostic:
B27: Recommendation:

Sheet 06_Contact
C2: =Summary!D26 -> 0
B3: =Summary!B27 -> 06_Contact | C3: Desktop | D3: With Cache
D4: Without Cache
C5: Mobile | D5: With Cache
D6: Without Cache
B8: Best Insight
B9: URL: | C9: =E3 -> 0
B10: Diagnostic: | C10: Defer offscreen images
B11: Recommendation: | C11: Learn how to defer offscreen images
B24: Worst Insight
B25: URL: | C25: =E5 -> 0
B26: Diagnostic:
B27: Recommendation:

Sheet 07_Privacy
C2: =Summary!D30 -> 0
B3: =Summary!B31 -> 07_Privacy | C3: Desktop | D3: With Cache
D4: Without Cache
C5: Mobile | D5: With Cache
D6: Without Cache
B8: Best Insight
B9: URL: | C9: =E3 -> 0
B10: Diagnostic: | C10: Defer offscreen images
B11: Recommendation: | C11: Learn how to defer offscreen images
B24: Worst Insight
B25: URL: | C25: =E5 -> 0
B26: Diagnostic:
B27: Recommendation:

Sheet 08_Game Testing
C2: =Summary!D34 -> 0
B3: =Summary!B35 -> 08_Game Testing | C3: Desktop | D3: With Cache
D4: Without Cache
C5: Mobile | D5: With Cache
D6: Without Cache
B8: Best Insight
B9: URL: | C9: =E3 -> 0
B10: Diagnostic: | C10: Defer offscreen images
B11: Recommendation: | C11: Learn how to defer offscreen images
B24: Worst Insight
B25: URL: | C25: =E5 -> 0
B26: Diagnostic:
B27: Recommendation:
